Traceback (most recent call last):
  File "/usr/local/anaconda3/lib/python3.11/site-packages/jupyter_cache/executors/utils.py", line 58, in single_nb_execution
    executenb(
  File "/usr/local/anaconda3/lib/python3.11/site-packages/nbclient/client.py", line 1204, in execute
    return NotebookClient(nb=nb, resources=resources, km=km, **kwargs).execute()
           ^^^^^^^^^^^^^^^^^^^^^^^^^^^^^^^^^^^^^^^^^^^^^^^^^^^^^^^^^^^^^^^^^^^^^
  File "/usr/local/anaconda3/lib/python3.11/site-packages/nbclient/util.py", line 84, in wrapped
    return just_run(coro(*args, **kwargs))
           ^^^^^^^^^^^^^^^^^^^^^^^^^^^^^^^
  File "/usr/local/anaconda3/lib/python3.11/site-packages/nbclient/util.py", line 62, in just_run
    return loop.run_until_complete(coro)
           ^^^^^^^^^^^^^^^^^^^^^^^^^^^^^
  File "/usr/local/anaconda3/lib/python3.11/asyncio/base_events.py", line 653, in run_until_complete
    return future.result()
           ^^^^^^^^^^^^^^^
  File "/usr/local/anaconda3/lib/python3.11/site-packages/nbclient/client.py", line 663, in async_execute
    await self.async_execute_cell(
  File "/usr/local/anaconda3/lib/python3.11/site-packages/nbclient/client.py", line 965, in async_execute_cell
    await self._check_raise_for_error(cell, cell_index, exec_reply)
  File "/usr/local/anaconda3/lib/python3.11/site-packages/nbclient/client.py", line 862, in _check_raise_for_error
    raise CellExecutionError.from_cell_and_msg(cell, exec_reply_content)
nbclient.exceptions.CellExecutionError: An error occurred while executing the following cell:
------------------
from faker import Faker

def generate_random_names(num_names):
    fake = Faker()
    names = [[fake.first_name(), fake.last_name()] for _ in range(num_names)]
    return names

def create_table(names):
    header = ["Number", "Name"]
    table = []
    table.append(header)
    for idx, name in enumerate(names, start=1):
        full_name = " ".join(name)
        row = [idx, full_name]
        table.append(row)

    # Printing the table
    for row in table:
        print(f"{row[0]:<10} {row[1]:<30}")

# Generate 10 random names and call the function
random_names = generate_random_names(10)
create_table(random_names)

------------------

[0;31m---------------------------------------------------------------------------[0m
[0;31mModuleNotFoundError[0m                       Traceback (most recent call last)
Cell [0;32mIn[1], line 1[0m
[0;32m----> 1[0m [38;5;28;01mfrom[39;00m [38;5;21;01mfaker[39;00m [38;5;28;01mimport[39;00m Faker
[1;32m      3[0m [38;5;28;01mdef[39;00m [38;5;21mgenerate_random_names[39m(num_names):
[1;32m      4[0m     fake [38;5;241m=[39m Faker()

[0;31mModuleNotFoundError[0m: No module named 'faker'
ModuleNotFoundError: No module named 'faker'

