Traceback (most recent call last):
  File "/Library/Frameworks/Python.framework/Versions/3.11/lib/python3.11/site-packages/jupyter_cache/executors/utils.py", line 58, in single_nb_execution
    executenb(
  File "/Library/Frameworks/Python.framework/Versions/3.11/lib/python3.11/site-packages/nbclient/client.py", line 1305, in execute
    return NotebookClient(nb=nb, resources=resources, km=km, **kwargs).execute()
           ^^^^^^^^^^^^^^^^^^^^^^^^^^^^^^^^^^^^^^^^^^^^^^^^^^^^^^^^^^^^^^^^^^^^^
  File "/Users/d/Library/Python/3.11/lib/python/site-packages/jupyter_core/utils/__init__.py", line 166, in wrapped
    return loop.run_until_complete(inner)
           ^^^^^^^^^^^^^^^^^^^^^^^^^^^^^^
  File "/Library/Frameworks/Python.framework/Versions/3.11/lib/python3.11/asyncio/base_events.py", line 653, in run_until_complete
    return future.result()
           ^^^^^^^^^^^^^^^
  File "/Library/Frameworks/Python.framework/Versions/3.11/lib/python3.11/site-packages/nbclient/client.py", line 705, in async_execute
    await self.async_execute_cell(
  File "/Library/Frameworks/Python.framework/Versions/3.11/lib/python3.11/site-packages/nbclient/client.py", line 1058, in async_execute_cell
    await self._check_raise_for_error(cell, cell_index, exec_reply)
  File "/Library/Frameworks/Python.framework/Versions/3.11/lib/python3.11/site-packages/nbclient/client.py", line 914, in _check_raise_for_error
    raise CellExecutionError.from_cell_and_msg(cell, exec_reply_content)
nbclient.exceptions.CellExecutionError: An error occurred while executing the following cell:
------------------
import streamlit as st
import requests as rq
import bs4
import pandas as pd
import plotly.express as px
import numpy as np
from dash import Dash, dcc, html, Input, Output

#st.title("GDP by Region")

url = 'https://en.wikipedia.org/wiki/List_of_countries_by_GDP_(nominal)'
page = rq.get(url)
page.text[0 : 99]

bs4page = bs4.BeautifulSoup(page.text, 'html.parser')

tables = bs4page.find('table',{'class':"wikitable"})

gdp = pd.read_html(str(tables))
gdp = pd.read_html(str(tables))[0]

## There's an empty row

gdp = gdp.rename(columns={"UN Region": "Region", "IMF[1][13]": "IMF", "World Bank[14]": "World Bank", "Country/Territory": "Country"})
gdp.IMF = gdp.IMF[gdp.IMF != "101560901"]


gdp.IMF = gdp.IMF[gdp.IMF != "101560901"]
gdp = gdp.drop(gdp.columns[3], axis=1)
gdp.IMF = gdp.IMF.apply(pd.to_numeric,errors='coerce')
gdp = gdp.dropna()

# gdp.dtypes
#gdp_imf = pd.to_numeric(gdp_imf, errors='coerce')
#gdp = gdp.dropna()

gdp = gdp.to_numpy()

regions = gdp[:, 1]
gdp_imf = gdp[:, 2]
countries = gdp[:,0]

colors = px.colors.qualitative.Pastel1 # set the color scheme

fig = px.bar(x=regions, y=gdp_imf, color_discrete_sequence=colors, hover_data=[gdp_imf])
fig.update_layout(template='plotly')
fig.update_xaxes(title_text="Region")
fig.update_yaxes(title_text="GDP as per IMF (in USD)")
------------------


[0;31m---------------------------------------------------------------------------[0m
[0;31mgaierror[0m                                  Traceback (most recent call last)
File [0;32m/Library/Frameworks/Python.framework/Versions/3.11/lib/python3.11/site-packages/urllib3/connection.py:169[0m, in [0;36mHTTPConnection._new_conn[0;34m(self)[0m
[1;32m    168[0m [38;5;28;01mtry[39;00m:
[0;32m--> 169[0m     conn [38;5;241m=[39m [43mconnection[49m[38;5;241;43m.[39;49m[43mcreate_connection[49m[43m([49m
[1;32m    170[0m [43m        [49m[43m([49m[38;5;28;43mself[39;49m[38;5;241;43m.[39;49m[43m_dns_host[49m[43m,[49m[43m [49m[38;5;28;43mself[39;49m[38;5;241;43m.[39;49m[43mport[49m[43m)[49m[43m,[49m[43m [49m[38;5;28;43mself[39;49m[38;5;241;43m.[39;49m[43mtimeout[49m[43m,[49m[43m [49m[38;5;241;43m*[39;49m[38;5;241;43m*[39;49m[43mextra_kw[49m
[1;32m    171[0m [43m    [49m[43m)[49m
[1;32m    173[0m [38;5;28;01mexcept[39;00m SocketTimeout:

File [0;32m/Library/Frameworks/Python.framework/Versions/3.11/lib/python3.11/site-packages/urllib3/util/connection.py:73[0m, in [0;36mcreate_connection[0;34m(address, timeout, source_address, socket_options)[0m
[1;32m     69[0m     [38;5;28;01mreturn[39;00m six[38;5;241m.[39mraise_from(
[1;32m     70[0m         LocationParseError([38;5;124mu[39m[38;5;124m"[39m[38;5;124m'[39m[38;5;132;01m%s[39;00m[38;5;124m'[39m[38;5;124m, label empty or too long[39m[38;5;124m"[39m [38;5;241m%[39m host), [38;5;28;01mNone[39;00m
[1;32m     71[0m     )
[0;32m---> 73[0m [38;5;28;01mfor[39;00m res [38;5;129;01min[39;00m [43msocket[49m[38;5;241;43m.[39;49m[43mgetaddrinfo[49m[43m([49m[43mhost[49m[43m,[49m[43m [49m[43mport[49m[43m,[49m[43m [49m[43mfamily[49m[43m,[49m[43m [49m[43msocket[49m[38;5;241;43m.[39;49m[43mSOCK_STREAM[49m[43m)[49m:
[1;32m     74[0m     af, socktype, proto, canonname, sa [38;5;241m=[39m res

File [0;32m/Library/Frameworks/Python.framework/Versions/3.11/lib/python3.11/socket.py:962[0m, in [0;36mgetaddrinfo[0;34m(host, port, family, type, proto, flags)[0m
[1;32m    961[0m addrlist [38;5;241m=[39m []
[0;32m--> 962[0m [38;5;28;01mfor[39;00m res [38;5;129;01min[39;00m [43m_socket[49m[38;5;241;43m.[39;49m[43mgetaddrinfo[49m[43m([49m[43mhost[49m[43m,[49m[43m [49m[43mport[49m[43m,[49m[43m [49m[43mfamily[49m[43m,[49m[43m [49m[38;5;28;43mtype[39;49m[43m,[49m[43m [49m[43mproto[49m[43m,[49m[43m [49m[43mflags[49m[43m)[49m:
[1;32m    963[0m     af, socktype, proto, canonname, sa [38;5;241m=[39m res

[0;31mgaierror[0m: [Errno 8] nodename nor servname provided, or not known

During handling of the above exception, another exception occurred:

[0;31mNewConnectionError[0m                        Traceback (most recent call last)
File [0;32m/Library/Frameworks/Python.framework/Versions/3.11/lib/python3.11/site-packages/urllib3/connectionpool.py:699[0m, in [0;36mHTTPConnectionPool.urlopen[0;34m(self, method, url, body, headers, retries, redirect, assert_same_host, timeout, pool_timeout, release_conn, chunked, body_pos, **response_kw)[0m
[1;32m    698[0m [38;5;66;03m# Make the request on the httplib connection object.[39;00m
[0;32m--> 699[0m httplib_response [38;5;241m=[39m [38;5;28;43mself[39;49m[38;5;241;43m.[39;49m[43m_make_request[49m[43m([49m
[1;32m    700[0m [43m    [49m[43mconn[49m[43m,[49m
[1;32m    701[0m [43m    [49m[43mmethod[49m[43m,[49m
[1;32m    702[0m [43m    [49m[43murl[49m[43m,[49m
[1;32m    703[0m [43m    [49m[43mtimeout[49m[38;5;241;43m=[39;49m[43mtimeout_obj[49m[43m,[49m
[1;32m    704[0m [43m    [49m[43mbody[49m[38;5;241;43m=[39;49m[43mbody[49m[43m,[49m
[1;32m    705[0m [43m    [49m[43mheaders[49m[38;5;241;43m=[39;49m[43mheaders[49m[43m,[49m
[1;32m    706[0m [43m    [49m[43mchunked[49m[38;5;241;43m=[39;49m[43mchunked[49m[43m,[49m
[1;32m    707[0m [43m[49m[43m)[49m
[1;32m    709[0m [38;5;66;03m# If we're going to release the connection in ``finally:``, then[39;00m
[1;32m    710[0m [38;5;66;03m# the response doesn't need to know about the connection. Otherwise[39;00m
[1;32m    711[0m [38;5;66;03m# it will also try to release it and we'll have a double-release[39;00m
[1;32m    712[0m [38;5;66;03m# mess.[39;00m

File [0;32m/Library/Frameworks/Python.framework/Versions/3.11/lib/python3.11/site-packages/urllib3/connectionpool.py:382[0m, in [0;36mHTTPConnectionPool._make_request[0;34m(self, conn, method, url, timeout, chunked, **httplib_request_kw)[0m
[1;32m    381[0m [38;5;28;01mtry[39;00m:
[0;32m--> 382[0m     [38;5;28;43mself[39;49m[38;5;241;43m.[39;49m[43m_validate_conn[49m[43m([49m[43mconn[49m[43m)[49m
[1;32m    383[0m [38;5;28;01mexcept[39;00m (SocketTimeout, BaseSSLError) [38;5;28;01mas[39;00m e:
[1;32m    384[0m     [38;5;66;03m# Py2 raises this as a BaseSSLError, Py3 raises it as socket timeout.[39;00m

File [0;32m/Library/Frameworks/Python.framework/Versions/3.11/lib/python3.11/site-packages/urllib3/connectionpool.py:1010[0m, in [0;36mHTTPSConnectionPool._validate_conn[0;34m(self, conn)[0m
[1;32m   1009[0m [38;5;28;01mif[39;00m [38;5;129;01mnot[39;00m [38;5;28mgetattr[39m(conn, [38;5;124m"[39m[38;5;124msock[39m[38;5;124m"[39m, [38;5;28;01mNone[39;00m):  [38;5;66;03m# AppEngine might not have  `.sock`[39;00m
[0;32m-> 1010[0m     [43mconn[49m[38;5;241;43m.[39;49m[43mconnect[49m[43m([49m[43m)[49m
[1;32m   1012[0m [38;5;28;01mif[39;00m [38;5;129;01mnot[39;00m conn[38;5;241m.[39mis_verified:

File [0;32m/Library/Frameworks/Python.framework/Versions/3.11/lib/python3.11/site-packages/urllib3/connection.py:353[0m, in [0;36mHTTPSConnection.connect[0;34m(self)[0m
[1;32m    351[0m [38;5;28;01mdef[39;00m [38;5;21mconnect[39m([38;5;28mself[39m):
[1;32m    352[0m     [38;5;66;03m# Add certificate verification[39;00m
[0;32m--> 353[0m     conn [38;5;241m=[39m [38;5;28;43mself[39;49m[38;5;241;43m.[39;49m[43m_new_conn[49m[43m([49m[43m)[49m
[1;32m    354[0m     hostname [38;5;241m=[39m [38;5;28mself[39m[38;5;241m.[39mhost

File [0;32m/Library/Frameworks/Python.framework/Versions/3.11/lib/python3.11/site-packages/urllib3/connection.py:181[0m, in [0;36mHTTPConnection._new_conn[0;34m(self)[0m
[1;32m    180[0m [38;5;28;01mexcept[39;00m SocketError [38;5;28;01mas[39;00m e:
[0;32m--> 181[0m     [38;5;28;01mraise[39;00m NewConnectionError(
[1;32m    182[0m         [38;5;28mself[39m, [38;5;124m"[39m[38;5;124mFailed to establish a new connection: [39m[38;5;132;01m%s[39;00m[38;5;124m"[39m [38;5;241m%[39m e
[1;32m    183[0m     )
[1;32m    185[0m [38;5;28;01mreturn[39;00m conn

[0;31mNewConnectionError[0m: <urllib3.connection.HTTPSConnection object at 0x13a6d1510>: Failed to establish a new connection: [Errno 8] nodename nor servname provided, or not known

During handling of the above exception, another exception occurred:

[0;31mMaxRetryError[0m                             Traceback (most recent call last)
File [0;32m/Library/Frameworks/Python.framework/Versions/3.11/lib/python3.11/site-packages/requests/adapters.py:486[0m, in [0;36mHTTPAdapter.send[0;34m(self, request, stream, timeout, verify, cert, proxies)[0m
[1;32m    485[0m [38;5;28;01mtry[39;00m:
[0;32m--> 486[0m     resp [38;5;241m=[39m [43mconn[49m[38;5;241;43m.[39;49m[43murlopen[49m[43m([49m
[1;32m    487[0m [43m        [49m[43mmethod[49m[38;5;241;43m=[39;49m[43mrequest[49m[38;5;241;43m.[39;49m[43mmethod[49m[43m,[49m
[1;32m    488[0m [43m        [49m[43murl[49m[38;5;241;43m=[39;49m[43murl[49m[43m,[49m
[1;32m    489[0m [43m        [49m[43mbody[49m[38;5;241;43m=[39;49m[43mrequest[49m[38;5;241;43m.[39;49m[43mbody[49m[43m,[49m
[1;32m    490[0m [43m        [49m[43mheaders[49m[38;5;241;43m=[39;49m[43mrequest[49m[38;5;241;43m.[39;49m[43mheaders[49m[43m,[49m
[1;32m    491[0m [43m        [49m[43mredirect[49m[38;5;241;43m=[39;49m[38;5;28;43;01mFalse[39;49;00m[43m,[49m
[1;32m    492[0m [43m        [49m[43massert_same_host[49m[38;5;241;43m=[39;49m[38;5;28;43;01mFalse[39;49;00m[43m,[49m
[1;32m    493[0m [43m        [49m[43mpreload_content[49m[38;5;241;43m=[39;49m[38;5;28;43;01mFalse[39;49;00m[43m,[49m
[1;32m    494[0m [43m        [49m[43mdecode_content[49m[38;5;241;43m=[39;49m[38;5;28;43;01mFalse[39;49;00m[43m,[49m
[1;32m    495[0m [43m        [49m[43mretries[49m[38;5;241;43m=[39;49m[38;5;28;43mself[39;49m[38;5;241;43m.[39;49m[43mmax_retries[49m[43m,[49m
[1;32m    496[0m [43m        [49m[43mtimeout[49m[38;5;241;43m=[39;49m[43mtimeout[49m[43m,[49m
[1;32m    497[0m [43m        [49m[43mchunked[49m[38;5;241;43m=[39;49m[43mchunked[49m[43m,[49m
[1;32m    498[0m [43m    [49m[43m)[49m
[1;32m    500[0m [38;5;28;01mexcept[39;00m (ProtocolError, [38;5;167;01mOSError[39;00m) [38;5;28;01mas[39;00m err:

File [0;32m/Library/Frameworks/Python.framework/Versions/3.11/lib/python3.11/site-packages/urllib3/connectionpool.py:755[0m, in [0;36mHTTPConnectionPool.urlopen[0;34m(self, method, url, body, headers, retries, redirect, assert_same_host, timeout, pool_timeout, release_conn, chunked, body_pos, **response_kw)[0m
[1;32m    753[0m     e [38;5;241m=[39m ProtocolError([38;5;124m"[39m[38;5;124mConnection aborted.[39m[38;5;124m"[39m, e)
[0;32m--> 755[0m retries [38;5;241m=[39m [43mretries[49m[38;5;241;43m.[39;49m[43mincrement[49m[43m([49m
[1;32m    756[0m [43m    [49m[43mmethod[49m[43m,[49m[43m [49m[43murl[49m[43m,[49m[43m [49m[43merror[49m[38;5;241;43m=[39;49m[43me[49m[43m,[49m[43m [49m[43m_pool[49m[38;5;241;43m=[39;49m[38;5;28;43mself[39;49m[43m,[49m[43m [49m[43m_stacktrace[49m[38;5;241;43m=[39;49m[43msys[49m[38;5;241;43m.[39;49m[43mexc_info[49m[43m([49m[43m)[49m[43m[[49m[38;5;241;43m2[39;49m[43m][49m
[1;32m    757[0m [43m[49m[43m)[49m
[1;32m    758[0m retries[38;5;241m.[39msleep()

File [0;32m/Library/Frameworks/Python.framework/Versions/3.11/lib/python3.11/site-packages/urllib3/util/retry.py:574[0m, in [0;36mRetry.increment[0;34m(self, method, url, response, error, _pool, _stacktrace)[0m
[1;32m    573[0m [38;5;28;01mif[39;00m new_retry[38;5;241m.[39mis_exhausted():
[0;32m--> 574[0m     [38;5;28;01mraise[39;00m MaxRetryError(_pool, url, error [38;5;129;01mor[39;00m ResponseError(cause))
[1;32m    576[0m log[38;5;241m.[39mdebug([38;5;124m"[39m[38;5;124mIncremented Retry for (url=[39m[38;5;124m'[39m[38;5;132;01m%s[39;00m[38;5;124m'[39m[38;5;124m): [39m[38;5;132;01m%r[39;00m[38;5;124m"[39m, url, new_retry)

[0;31mMaxRetryError[0m: HTTPSConnectionPool(host='en.wikipedia.org', port=443): Max retries exceeded with url: /wiki/List_of_countries_by_GDP_(nominal) (Caused by NewConnectionError('<urllib3.connection.HTTPSConnection object at 0x13a6d1510>: Failed to establish a new connection: [Errno 8] nodename nor servname provided, or not known'))

During handling of the above exception, another exception occurred:

[0;31mConnectionError[0m                           Traceback (most recent call last)
Cell [0;32mIn[1], line 12[0m
[1;32m      9[0m [38;5;66;03m#st.title("GDP by Region")[39;00m
[1;32m     11[0m url [38;5;241m=[39m [38;5;124m'[39m[38;5;124mhttps://en.wikipedia.org/wiki/List_of_countries_by_GDP_(nominal)[39m[38;5;124m'[39m
[0;32m---> 12[0m page [38;5;241m=[39m [43mrq[49m[38;5;241;43m.[39;49m[43mget[49m[43m([49m[43murl[49m[43m)[49m
[1;32m     13[0m page[38;5;241m.[39mtext[[38;5;241m0[39m : [38;5;241m99[39m]
[1;32m     15[0m bs4page [38;5;241m=[39m bs4[38;5;241m.[39mBeautifulSoup(page[38;5;241m.[39mtext, [38;5;124m'[39m[38;5;124mhtml.parser[39m[38;5;124m'[39m)

File [0;32m/Library/Frameworks/Python.framework/Versions/3.11/lib/python3.11/site-packages/requests/api.py:73[0m, in [0;36mget[0;34m(url, params, **kwargs)[0m
[1;32m     62[0m [38;5;28;01mdef[39;00m [38;5;21mget[39m(url, params[38;5;241m=[39m[38;5;28;01mNone[39;00m, [38;5;241m*[39m[38;5;241m*[39mkwargs):
[1;32m     63[0m [38;5;250m    [39m[38;5;124mr[39m[38;5;124;03m"""Sends a GET request.[39;00m
[1;32m     64[0m 
[1;32m     65[0m [38;5;124;03m    :param url: URL for the new :class:`Request` object.[39;00m
[0;32m   (...)[0m
[1;32m     70[0m [38;5;124;03m    :rtype: requests.Response[39;00m
[1;32m     71[0m [38;5;124;03m    """[39;00m
[0;32m---> 73[0m     [38;5;28;01mreturn[39;00m [43mrequest[49m[43m([49m[38;5;124;43m"[39;49m[38;5;124;43mget[39;49m[38;5;124;43m"[39;49m[43m,[49m[43m [49m[43murl[49m[43m,[49m[43m [49m[43mparams[49m[38;5;241;43m=[39;49m[43mparams[49m[43m,[49m[43m [49m[38;5;241;43m*[39;49m[38;5;241;43m*[39;49m[43mkwargs[49m[43m)[49m

File [0;32m/Library/Frameworks/Python.framework/Versions/3.11/lib/python3.11/site-packages/requests/api.py:59[0m, in [0;36mrequest[0;34m(method, url, **kwargs)[0m
[1;32m     55[0m [38;5;66;03m# By using the 'with' statement we are sure the session is closed, thus we[39;00m
[1;32m     56[0m [38;5;66;03m# avoid leaving sockets open which can trigger a ResourceWarning in some[39;00m
[1;32m     57[0m [38;5;66;03m# cases, and look like a memory leak in others.[39;00m
[1;32m     58[0m [38;5;28;01mwith[39;00m sessions[38;5;241m.[39mSession() [38;5;28;01mas[39;00m session:
[0;32m---> 59[0m     [38;5;28;01mreturn[39;00m [43msession[49m[38;5;241;43m.[39;49m[43mrequest[49m[43m([49m[43mmethod[49m[38;5;241;43m=[39;49m[43mmethod[49m[43m,[49m[43m [49m[43murl[49m[38;5;241;43m=[39;49m[43murl[49m[43m,[49m[43m [49m[38;5;241;43m*[39;49m[38;5;241;43m*[39;49m[43mkwargs[49m[43m)[49m

File [0;32m/Library/Frameworks/Python.framework/Versions/3.11/lib/python3.11/site-packages/requests/sessions.py:589[0m, in [0;36mSession.request[0;34m(self, method, url, params, data, headers, cookies, files, auth, timeout, allow_redirects, proxies, hooks, stream, verify, cert, json)[0m
[1;32m    584[0m send_kwargs [38;5;241m=[39m {
[1;32m    585[0m     [38;5;124m"[39m[38;5;124mtimeout[39m[38;5;124m"[39m: timeout,
[1;32m    586[0m     [38;5;124m"[39m[38;5;124mallow_redirects[39m[38;5;124m"[39m: allow_redirects,
[1;32m    587[0m }
[1;32m    588[0m send_kwargs[38;5;241m.[39mupdate(settings)
[0;32m--> 589[0m resp [38;5;241m=[39m [38;5;28;43mself[39;49m[38;5;241;43m.[39;49m[43msend[49m[43m([49m[43mprep[49m[43m,[49m[43m [49m[38;5;241;43m*[39;49m[38;5;241;43m*[39;49m[43msend_kwargs[49m[43m)[49m
[1;32m    591[0m [38;5;28;01mreturn[39;00m resp

File [0;32m/Library/Frameworks/Python.framework/Versions/3.11/lib/python3.11/site-packages/requests/sessions.py:703[0m, in [0;36mSession.send[0;34m(self, request, **kwargs)[0m
[1;32m    700[0m start [38;5;241m=[39m preferred_clock()
[1;32m    702[0m [38;5;66;03m# Send the request[39;00m
[0;32m--> 703[0m r [38;5;241m=[39m [43madapter[49m[38;5;241;43m.[39;49m[43msend[49m[43m([49m[43mrequest[49m[43m,[49m[43m [49m[38;5;241;43m*[39;49m[38;5;241;43m*[39;49m[43mkwargs[49m[43m)[49m
[1;32m    705[0m [38;5;66;03m# Total elapsed time of the request (approximately)[39;00m
[1;32m    706[0m elapsed [38;5;241m=[39m preferred_clock() [38;5;241m-[39m start

File [0;32m/Library/Frameworks/Python.framework/Versions/3.11/lib/python3.11/site-packages/requests/adapters.py:519[0m, in [0;36mHTTPAdapter.send[0;34m(self, request, stream, timeout, verify, cert, proxies)[0m
[1;32m    515[0m     [38;5;28;01mif[39;00m [38;5;28misinstance[39m(e[38;5;241m.[39mreason, _SSLError):
[1;32m    516[0m         [38;5;66;03m# This branch is for urllib3 v1.22 and later.[39;00m
[1;32m    517[0m         [38;5;28;01mraise[39;00m SSLError(e, request[38;5;241m=[39mrequest)
[0;32m--> 519[0m     [38;5;28;01mraise[39;00m [38;5;167;01mConnectionError[39;00m(e, request[38;5;241m=[39mrequest)
[1;32m    521[0m [38;5;28;01mexcept[39;00m ClosedPoolError [38;5;28;01mas[39;00m e:
[1;32m    522[0m     [38;5;28;01mraise[39;00m [38;5;167;01mConnectionError[39;00m(e, request[38;5;241m=[39mrequest)

[0;31mConnectionError[0m: HTTPSConnectionPool(host='en.wikipedia.org', port=443): Max retries exceeded with url: /wiki/List_of_countries_by_GDP_(nominal) (Caused by NewConnectionError('<urllib3.connection.HTTPSConnection object at 0x13a6d1510>: Failed to establish a new connection: [Errno 8] nodename nor servname provided, or not known'))

